[2024-12-09T01:33:19.712+0000] {processor.py:186} INFO - Started process (PID=77) to work on /home/airflow/.local/lib/python3.12/site-packages/airflow/example_dags/example_trigger_target_dag.py
[2024-12-09T01:33:19.714+0000] {processor.py:914} INFO - Processing file /home/airflow/.local/lib/python3.12/site-packages/airflow/example_dags/example_trigger_target_dag.py for tasks to queue
[2024-12-09T01:33:19.719+0000] {logging_mixin.py:190} INFO - [2024-12-09T01:33:19.718+0000] {dagbag.py:588} INFO - Filling up the DagBag from /home/airflow/.local/lib/python3.12/site-packages/airflow/example_dags/example_trigger_target_dag.py
[2024-12-09T01:33:19.737+0000] {processor.py:925} INFO - DAG(s) 'example_trigger_target_dag' retrieved from /home/airflow/.local/lib/python3.12/site-packages/airflow/example_dags/example_trigger_target_dag.py
[2024-12-09T01:33:19.907+0000] {logging_mixin.py:190} INFO - [2024-12-09T01:33:19.906+0000] {override.py:1911} INFO - Created Permission View: can edit on DAG:example_trigger_target_dag
[2024-12-09T01:33:19.924+0000] {logging_mixin.py:190} INFO - [2024-12-09T01:33:19.923+0000] {override.py:1911} INFO - Created Permission View: can delete on DAG:example_trigger_target_dag
[2024-12-09T01:33:19.933+0000] {logging_mixin.py:190} INFO - [2024-12-09T01:33:19.933+0000] {override.py:1911} INFO - Created Permission View: can read on DAG:example_trigger_target_dag
[2024-12-09T01:33:19.943+0000] {logging_mixin.py:190} INFO - [2024-12-09T01:33:19.943+0000] {override.py:1911} INFO - Created Permission View: can delete on DAG Run:example_trigger_target_dag
[2024-12-09T01:33:19.953+0000] {logging_mixin.py:190} INFO - [2024-12-09T01:33:19.952+0000] {override.py:1911} INFO - Created Permission View: menu access on DAG Run:example_trigger_target_dag
[2024-12-09T01:33:19.963+0000] {logging_mixin.py:190} INFO - [2024-12-09T01:33:19.962+0000] {override.py:1911} INFO - Created Permission View: can create on DAG Run:example_trigger_target_dag
[2024-12-09T01:33:19.973+0000] {logging_mixin.py:190} INFO - [2024-12-09T01:33:19.973+0000] {override.py:1911} INFO - Created Permission View: can read on DAG Run:example_trigger_target_dag
[2024-12-09T01:33:19.974+0000] {logging_mixin.py:190} INFO - [2024-12-09T01:33:19.974+0000] {dag.py:3239} INFO - Sync 1 DAGs
[2024-12-09T01:33:19.999+0000] {logging_mixin.py:190} INFO - [2024-12-09T01:33:19.999+0000] {dag.py:3262} INFO - Creating ORM DAG for example_trigger_target_dag
[2024-12-09T01:33:20.001+0000] {logging_mixin.py:190} INFO - [2024-12-09T01:33:20.001+0000] {dag.py:4180} INFO - Setting next_dagrun for example_trigger_target_dag to None, run_after=None
[2024-12-09T01:33:20.033+0000] {processor.py:208} INFO - Processing /home/airflow/.local/lib/python3.12/site-packages/airflow/example_dags/example_trigger_target_dag.py took 0.335 seconds
[2024-12-09T01:33:50.393+0000] {processor.py:186} INFO - Started process (PID=140) to work on /home/airflow/.local/lib/python3.12/site-packages/airflow/example_dags/example_trigger_target_dag.py
[2024-12-09T01:33:50.394+0000] {processor.py:914} INFO - Processing file /home/airflow/.local/lib/python3.12/site-packages/airflow/example_dags/example_trigger_target_dag.py for tasks to queue
[2024-12-09T01:33:50.396+0000] {logging_mixin.py:190} INFO - [2024-12-09T01:33:50.396+0000] {dagbag.py:588} INFO - Filling up the DagBag from /home/airflow/.local/lib/python3.12/site-packages/airflow/example_dags/example_trigger_target_dag.py
[2024-12-09T01:33:50.404+0000] {processor.py:925} INFO - DAG(s) 'example_trigger_target_dag' retrieved from /home/airflow/.local/lib/python3.12/site-packages/airflow/example_dags/example_trigger_target_dag.py
[2024-12-09T01:33:50.423+0000] {logging_mixin.py:190} INFO - [2024-12-09T01:33:50.422+0000] {dag.py:3239} INFO - Sync 1 DAGs
[2024-12-09T01:33:50.436+0000] {logging_mixin.py:190} INFO - [2024-12-09T01:33:50.436+0000] {dag.py:4180} INFO - Setting next_dagrun for example_trigger_target_dag to None, run_after=None
[2024-12-09T01:33:50.459+0000] {processor.py:208} INFO - Processing /home/airflow/.local/lib/python3.12/site-packages/airflow/example_dags/example_trigger_target_dag.py took 0.072 seconds
[2024-12-09T01:34:21.702+0000] {processor.py:186} INFO - Started process (PID=203) to work on /home/airflow/.local/lib/python3.12/site-packages/airflow/example_dags/example_trigger_target_dag.py
[2024-12-09T01:34:21.793+0000] {processor.py:914} INFO - Processing file /home/airflow/.local/lib/python3.12/site-packages/airflow/example_dags/example_trigger_target_dag.py for tasks to queue
[2024-12-09T01:34:21.796+0000] {logging_mixin.py:190} INFO - [2024-12-09T01:34:21.796+0000] {dagbag.py:588} INFO - Filling up the DagBag from /home/airflow/.local/lib/python3.12/site-packages/airflow/example_dags/example_trigger_target_dag.py
[2024-12-09T01:34:21.817+0000] {processor.py:925} INFO - DAG(s) 'example_trigger_target_dag' retrieved from /home/airflow/.local/lib/python3.12/site-packages/airflow/example_dags/example_trigger_target_dag.py
[2024-12-09T01:34:22.341+0000] {logging_mixin.py:190} INFO - [2024-12-09T01:34:22.341+0000] {dag.py:3239} INFO - Sync 1 DAGs
[2024-12-09T01:34:22.361+0000] {logging_mixin.py:190} INFO - [2024-12-09T01:34:22.361+0000] {dag.py:4180} INFO - Setting next_dagrun for example_trigger_target_dag to None, run_after=None
[2024-12-09T01:34:22.388+0000] {processor.py:208} INFO - Processing /home/airflow/.local/lib/python3.12/site-packages/airflow/example_dags/example_trigger_target_dag.py took 0.699 seconds
[2024-12-09T01:34:53.123+0000] {processor.py:186} INFO - Started process (PID=266) to work on /home/airflow/.local/lib/python3.12/site-packages/airflow/example_dags/example_trigger_target_dag.py
[2024-12-09T01:34:53.124+0000] {processor.py:914} INFO - Processing file /home/airflow/.local/lib/python3.12/site-packages/airflow/example_dags/example_trigger_target_dag.py for tasks to queue
[2024-12-09T01:34:53.127+0000] {logging_mixin.py:190} INFO - [2024-12-09T01:34:53.127+0000] {dagbag.py:588} INFO - Filling up the DagBag from /home/airflow/.local/lib/python3.12/site-packages/airflow/example_dags/example_trigger_target_dag.py
[2024-12-09T01:34:53.137+0000] {processor.py:925} INFO - DAG(s) 'example_trigger_target_dag' retrieved from /home/airflow/.local/lib/python3.12/site-packages/airflow/example_dags/example_trigger_target_dag.py
[2024-12-09T01:34:53.159+0000] {logging_mixin.py:190} INFO - [2024-12-09T01:34:53.159+0000] {dag.py:3239} INFO - Sync 1 DAGs
[2024-12-09T01:34:53.180+0000] {logging_mixin.py:190} INFO - [2024-12-09T01:34:53.180+0000] {dag.py:4180} INFO - Setting next_dagrun for example_trigger_target_dag to None, run_after=None
[2024-12-09T01:34:53.209+0000] {processor.py:208} INFO - Processing /home/airflow/.local/lib/python3.12/site-packages/airflow/example_dags/example_trigger_target_dag.py took 0.094 seconds
[2024-12-09T01:39:04.412+0000] {processor.py:186} INFO - Started process (PID=288) to work on /home/airflow/.local/lib/python3.12/site-packages/airflow/example_dags/example_trigger_target_dag.py
[2024-12-09T01:39:04.413+0000] {processor.py:914} INFO - Processing file /home/airflow/.local/lib/python3.12/site-packages/airflow/example_dags/example_trigger_target_dag.py for tasks to queue
[2024-12-09T01:39:04.418+0000] {logging_mixin.py:190} INFO - [2024-12-09T01:39:04.418+0000] {dagbag.py:588} INFO - Filling up the DagBag from /home/airflow/.local/lib/python3.12/site-packages/airflow/example_dags/example_trigger_target_dag.py
[2024-12-09T01:39:04.436+0000] {processor.py:925} INFO - DAG(s) 'example_trigger_target_dag' retrieved from /home/airflow/.local/lib/python3.12/site-packages/airflow/example_dags/example_trigger_target_dag.py
[2024-12-09T01:39:04.515+0000] {logging_mixin.py:190} INFO - [2024-12-09T01:39:04.511+0000] {dag.py:3239} INFO - Sync 1 DAGs
[2024-12-09T01:39:04.561+0000] {logging_mixin.py:190} INFO - [2024-12-09T01:39:04.561+0000] {dag.py:4180} INFO - Setting next_dagrun for example_trigger_target_dag to None, run_after=None
[2024-12-09T01:39:04.620+0000] {processor.py:958} ERROR - Error logging import errors!
Traceback (most recent call last):
  File "/home/airflow/.local/lib/python3.12/site-packages/sqlalchemy/pool/base.py", line 936, in _checkout
    raise exc.InvalidatePoolError()
sqlalchemy.exc.InvalidatePoolError: ()

During handling of the above exception, another exception occurred:

Traceback (most recent call last):
  File "/home/airflow/.local/lib/python3.12/site-packages/sqlalchemy/engine/base.py", line 3371, in _wrap_pool_connect
    return fn()
           ^^^^
  File "/home/airflow/.local/lib/python3.12/site-packages/sqlalchemy/pool/base.py", line 327, in connect
    return _ConnectionFairy._checkout(self)
           ^^^^^^^^^^^^^^^^^^^^^^^^^^^^^^^^
  File "/home/airflow/.local/lib/python3.12/site-packages/sqlalchemy/pool/base.py", line 970, in _checkout
    with util.safe_reraise():
         ^^^^^^^^^^^^^^^^^^^
  File "/home/airflow/.local/lib/python3.12/site-packages/sqlalchemy/util/langhelpers.py", line 70, in __exit__
    compat.raise_(
  File "/home/airflow/.local/lib/python3.12/site-packages/sqlalchemy/util/compat.py", line 211, in raise_
    raise exception
  File "/home/airflow/.local/lib/python3.12/site-packages/sqlalchemy/pool/base.py", line 967, in _checkout
    fairy._connection_record.get_connection()
  File "/home/airflow/.local/lib/python3.12/site-packages/sqlalchemy/pool/base.py", line 630, in get_connection
    self.__connect()
  File "/home/airflow/.local/lib/python3.12/site-packages/sqlalchemy/pool/base.py", line 690, in __connect
    with util.safe_reraise():
         ^^^^^^^^^^^^^^^^^^^
  File "/home/airflow/.local/lib/python3.12/site-packages/sqlalchemy/util/langhelpers.py", line 70, in __exit__
    compat.raise_(
  File "/home/airflow/.local/lib/python3.12/site-packages/sqlalchemy/util/compat.py", line 211, in raise_
    raise exception
  File "/home/airflow/.local/lib/python3.12/site-packages/sqlalchemy/pool/base.py", line 686, in __connect
    self.dbapi_connection = connection = pool._invoke_creator(self)
                                         ^^^^^^^^^^^^^^^^^^^^^^^^^^
  File "/home/airflow/.local/lib/python3.12/site-packages/sqlalchemy/engine/create.py", line 574, in connect
    return dialect.connect(*cargs, **cparams)
           ^^^^^^^^^^^^^^^^^^^^^^^^^^^^^^^^^^
  File "/home/airflow/.local/lib/python3.12/site-packages/sqlalchemy/engine/default.py", line 598, in connect
    return self.dbapi.connect(*cargs, **cparams)
           ^^^^^^^^^^^^^^^^^^^^^^^^^^^^^^^^^^^^^
  File "/home/airflow/.local/lib/python3.12/site-packages/psycopg2/__init__.py", line 122, in connect
    conn = _connect(dsn, connection_factory=connection_factory, **kwasync)
           ^^^^^^^^^^^^^^^^^^^^^^^^^^^^^^^^^^^^^^^^^^^^^^^^^^^^^^^^^^^^^^^
psycopg2.OperationalError: connection to server at "postgres" (172.21.0.2), port 5432 failed: FATAL:  the database system is shutting down


The above exception was the direct cause of the following exception:

Traceback (most recent call last):
  File "/home/airflow/.local/lib/python3.12/site-packages/airflow/dag_processing/processor.py", line 952, in process_file
    DagFileProcessor.update_import_errors(
  File "/home/airflow/.local/lib/python3.12/site-packages/airflow/api_internal/internal_api_call.py", line 166, in wrapper
    return func(*args, **kwargs)
           ^^^^^^^^^^^^^^^^^^^^^
  File "/home/airflow/.local/lib/python3.12/site-packages/airflow/utils/session.py", line 97, in wrapper
    return func(*args, session=session, **kwargs)
           ^^^^^^^^^^^^^^^^^^^^^^^^^^^^^^^^^^^^^^
  File "/home/airflow/.local/lib/python3.12/site-packages/airflow/dag_processing/processor.py", line 641, in update_import_errors
    session.execute(
  File "/home/airflow/.local/lib/python3.12/site-packages/sqlalchemy/orm/session.py", line 1716, in execute
    conn = self._connection_for_bind(bind)
           ^^^^^^^^^^^^^^^^^^^^^^^^^^^^^^^
  File "/home/airflow/.local/lib/python3.12/site-packages/sqlalchemy/orm/session.py", line 1555, in _connection_for_bind
    return self._transaction._connection_for_bind(
           ^^^^^^^^^^^^^^^^^^^^^^^^^^^^^^^^^^^^^^^
  File "/home/airflow/.local/lib/python3.12/site-packages/sqlalchemy/orm/session.py", line 750, in _connection_for_bind
    conn = bind.connect()
           ^^^^^^^^^^^^^^
  File "/home/airflow/.local/lib/python3.12/site-packages/sqlalchemy/future/engine.py", line 412, in connect
    return super(Engine, self).connect()
           ^^^^^^^^^^^^^^^^^^^^^^^^^^^^^
  File "/home/airflow/.local/lib/python3.12/site-packages/sqlalchemy/engine/base.py", line 3325, in connect
    return self._connection_cls(self, close_with_result=close_with_result)
           ^^^^^^^^^^^^^^^^^^^^^^^^^^^^^^^^^^^^^^^^^^^^^^^^^^^^^^^^^^^^^^^
  File "/home/airflow/.local/lib/python3.12/site-packages/sqlalchemy/engine/base.py", line 96, in __init__
    else engine.raw_connection()
         ^^^^^^^^^^^^^^^^^^^^^^^
  File "/home/airflow/.local/lib/python3.12/site-packages/sqlalchemy/engine/base.py", line 3404, in raw_connection
    return self._wrap_pool_connect(self.pool.connect, _connection)
           ^^^^^^^^^^^^^^^^^^^^^^^^^^^^^^^^^^^^^^^^^^^^^^^^^^^^^^^
  File "/home/airflow/.local/lib/python3.12/site-packages/sqlalchemy/engine/base.py", line 3374, in _wrap_pool_connect
    Connection._handle_dbapi_exception_noconnection(
  File "/home/airflow/.local/lib/python3.12/site-packages/sqlalchemy/engine/base.py", line 2208, in _handle_dbapi_exception_noconnection
    util.raise_(
  File "/home/airflow/.local/lib/python3.12/site-packages/sqlalchemy/util/compat.py", line 211, in raise_
    raise exception
  File "/home/airflow/.local/lib/python3.12/site-packages/sqlalchemy/engine/base.py", line 3371, in _wrap_pool_connect
    return fn()
           ^^^^
  File "/home/airflow/.local/lib/python3.12/site-packages/sqlalchemy/pool/base.py", line 327, in connect
    return _ConnectionFairy._checkout(self)
           ^^^^^^^^^^^^^^^^^^^^^^^^^^^^^^^^
  File "/home/airflow/.local/lib/python3.12/site-packages/sqlalchemy/pool/base.py", line 970, in _checkout
    with util.safe_reraise():
         ^^^^^^^^^^^^^^^^^^^
  File "/home/airflow/.local/lib/python3.12/site-packages/sqlalchemy/util/langhelpers.py", line 70, in __exit__
    compat.raise_(
  File "/home/airflow/.local/lib/python3.12/site-packages/sqlalchemy/util/compat.py", line 211, in raise_
    raise exception
  File "/home/airflow/.local/lib/python3.12/site-packages/sqlalchemy/pool/base.py", line 967, in _checkout
    fairy._connection_record.get_connection()
  File "/home/airflow/.local/lib/python3.12/site-packages/sqlalchemy/pool/base.py", line 630, in get_connection
    self.__connect()
  File "/home/airflow/.local/lib/python3.12/site-packages/sqlalchemy/pool/base.py", line 690, in __connect
    with util.safe_reraise():
         ^^^^^^^^^^^^^^^^^^^
  File "/home/airflow/.local/lib/python3.12/site-packages/sqlalchemy/util/langhelpers.py", line 70, in __exit__
    compat.raise_(
  File "/home/airflow/.local/lib/python3.12/site-packages/sqlalchemy/util/compat.py", line 211, in raise_
    raise exception
  File "/home/airflow/.local/lib/python3.12/site-packages/sqlalchemy/pool/base.py", line 686, in __connect
    self.dbapi_connection = connection = pool._invoke_creator(self)
                                         ^^^^^^^^^^^^^^^^^^^^^^^^^^
  File "/home/airflow/.local/lib/python3.12/site-packages/sqlalchemy/engine/create.py", line 574, in connect
    return dialect.connect(*cargs, **cparams)
           ^^^^^^^^^^^^^^^^^^^^^^^^^^^^^^^^^^
  File "/home/airflow/.local/lib/python3.12/site-packages/sqlalchemy/engine/default.py", line 598, in connect
    return self.dbapi.connect(*cargs, **cparams)
           ^^^^^^^^^^^^^^^^^^^^^^^^^^^^^^^^^^^^^
  File "/home/airflow/.local/lib/python3.12/site-packages/psycopg2/__init__.py", line 122, in connect
    conn = _connect(dsn, connection_factory=connection_factory, **kwasync)
           ^^^^^^^^^^^^^^^^^^^^^^^^^^^^^^^^^^^^^^^^^^^^^^^^^^^^^^^^^^^^^^^
sqlalchemy.exc.OperationalError: (psycopg2.OperationalError) connection to server at "postgres" (172.21.0.2), port 5432 failed: FATAL:  the database system is shutting down

(Background on this error at: https://sqlalche.me/e/14/e3q8)
[2024-12-09T01:39:04.689+0000] {processor.py:964} ERROR - Error logging DAG warnings.
Traceback (most recent call last):
  File "/home/airflow/.local/lib/python3.12/site-packages/sqlalchemy/engine/base.py", line 3371, in _wrap_pool_connect
    return fn()
           ^^^^
  File "/home/airflow/.local/lib/python3.12/site-packages/sqlalchemy/pool/base.py", line 327, in connect
    return _ConnectionFairy._checkout(self)
           ^^^^^^^^^^^^^^^^^^^^^^^^^^^^^^^^
  File "/home/airflow/.local/lib/python3.12/site-packages/sqlalchemy/pool/base.py", line 894, in _checkout
    fairy = _ConnectionRecord.checkout(pool)
            ^^^^^^^^^^^^^^^^^^^^^^^^^^^^^^^^
  File "/home/airflow/.local/lib/python3.12/site-packages/sqlalchemy/pool/base.py", line 497, in checkout
    with util.safe_reraise():
         ^^^^^^^^^^^^^^^^^^^
  File "/home/airflow/.local/lib/python3.12/site-packages/sqlalchemy/util/langhelpers.py", line 70, in __exit__
    compat.raise_(
  File "/home/airflow/.local/lib/python3.12/site-packages/sqlalchemy/util/compat.py", line 211, in raise_
    raise exception
  File "/home/airflow/.local/lib/python3.12/site-packages/sqlalchemy/pool/base.py", line 495, in checkout
    dbapi_connection = rec.get_connection()
                       ^^^^^^^^^^^^^^^^^^^^
  File "/home/airflow/.local/lib/python3.12/site-packages/sqlalchemy/pool/base.py", line 630, in get_connection
    self.__connect()
  File "/home/airflow/.local/lib/python3.12/site-packages/sqlalchemy/pool/base.py", line 690, in __connect
    with util.safe_reraise():
         ^^^^^^^^^^^^^^^^^^^
  File "/home/airflow/.local/lib/python3.12/site-packages/sqlalchemy/util/langhelpers.py", line 70, in __exit__
    compat.raise_(
  File "/home/airflow/.local/lib/python3.12/site-packages/sqlalchemy/util/compat.py", line 211, in raise_
    raise exception
  File "/home/airflow/.local/lib/python3.12/site-packages/sqlalchemy/pool/base.py", line 686, in __connect
    self.dbapi_connection = connection = pool._invoke_creator(self)
                                         ^^^^^^^^^^^^^^^^^^^^^^^^^^
  File "/home/airflow/.local/lib/python3.12/site-packages/sqlalchemy/engine/create.py", line 574, in connect
    return dialect.connect(*cargs, **cparams)
           ^^^^^^^^^^^^^^^^^^^^^^^^^^^^^^^^^^
  File "/home/airflow/.local/lib/python3.12/site-packages/sqlalchemy/engine/default.py", line 598, in connect
    return self.dbapi.connect(*cargs, **cparams)
           ^^^^^^^^^^^^^^^^^^^^^^^^^^^^^^^^^^^^^
  File "/home/airflow/.local/lib/python3.12/site-packages/psycopg2/__init__.py", line 122, in connect
    conn = _connect(dsn, connection_factory=connection_factory, **kwasync)
           ^^^^^^^^^^^^^^^^^^^^^^^^^^^^^^^^^^^^^^^^^^^^^^^^^^^^^^^^^^^^^^^
psycopg2.OperationalError: connection to server at "postgres" (172.21.0.2), port 5432 failed: FATAL:  the database system is shutting down


The above exception was the direct cause of the following exception:

Traceback (most recent call last):
  File "/home/airflow/.local/lib/python3.12/site-packages/airflow/dag_processing/processor.py", line 962, in process_file
    self.update_dag_warnings(dagbag=dagbag)
  File "/home/airflow/.local/lib/python3.12/site-packages/airflow/dag_processing/processor.py", line 694, in update_dag_warnings
    return DagFileProcessor._validate_task_pools_and_update_dag_warnings(pool_dict, dag_ids)
           ^^^^^^^^^^^^^^^^^^^^^^^^^^^^^^^^^^^^^^^^^^^^^^^^^^^^^^^^^^^^^^^^^^^^^^^^^^^^^^^^^
  File "/home/airflow/.local/lib/python3.12/site-packages/airflow/api_internal/internal_api_call.py", line 166, in wrapper
    return func(*args, **kwargs)
           ^^^^^^^^^^^^^^^^^^^^^
  File "/home/airflow/.local/lib/python3.12/site-packages/airflow/utils/session.py", line 97, in wrapper
    return func(*args, session=session, **kwargs)
           ^^^^^^^^^^^^^^^^^^^^^^^^^^^^^^^^^^^^^^
  File "/home/airflow/.local/lib/python3.12/site-packages/airflow/dag_processing/processor.py", line 704, in _validate_task_pools_and_update_dag_warnings
    all_pools = {p.pool for p in Pool.get_pools(session)}
                                 ^^^^^^^^^^^^^^^^^^^^^^^
  File "/home/airflow/.local/lib/python3.12/site-packages/airflow/utils/session.py", line 94, in wrapper
    return func(*args, **kwargs)
           ^^^^^^^^^^^^^^^^^^^^^
  File "/home/airflow/.local/lib/python3.12/site-packages/airflow/models/pool.py", line 69, in get_pools
    return session.scalars(select(Pool)).all()
           ^^^^^^^^^^^^^^^^^^^^^^^^^^^^^
  File "/home/airflow/.local/lib/python3.12/site-packages/sqlalchemy/orm/session.py", line 1778, in scalars
    return self.execute(
           ^^^^^^^^^^^^^
  File "/home/airflow/.local/lib/python3.12/site-packages/sqlalchemy/orm/session.py", line 1716, in execute
    conn = self._connection_for_bind(bind)
           ^^^^^^^^^^^^^^^^^^^^^^^^^^^^^^^
  File "/home/airflow/.local/lib/python3.12/site-packages/sqlalchemy/orm/session.py", line 1555, in _connection_for_bind
    return self._transaction._connection_for_bind(
           ^^^^^^^^^^^^^^^^^^^^^^^^^^^^^^^^^^^^^^^
  File "/home/airflow/.local/lib/python3.12/site-packages/sqlalchemy/orm/session.py", line 750, in _connection_for_bind
    conn = bind.connect()
           ^^^^^^^^^^^^^^
  File "/home/airflow/.local/lib/python3.12/site-packages/sqlalchemy/future/engine.py", line 412, in connect
    return super(Engine, self).connect()
           ^^^^^^^^^^^^^^^^^^^^^^^^^^^^^
  File "/home/airflow/.local/lib/python3.12/site-packages/sqlalchemy/engine/base.py", line 3325, in connect
    return self._connection_cls(self, close_with_result=close_with_result)
           ^^^^^^^^^^^^^^^^^^^^^^^^^^^^^^^^^^^^^^^^^^^^^^^^^^^^^^^^^^^^^^^
  File "/home/airflow/.local/lib/python3.12/site-packages/sqlalchemy/engine/base.py", line 96, in __init__
    else engine.raw_connection()
         ^^^^^^^^^^^^^^^^^^^^^^^
  File "/home/airflow/.local/lib/python3.12/site-packages/sqlalchemy/engine/base.py", line 3404, in raw_connection
    return self._wrap_pool_connect(self.pool.connect, _connection)
           ^^^^^^^^^^^^^^^^^^^^^^^^^^^^^^^^^^^^^^^^^^^^^^^^^^^^^^^
  File "/home/airflow/.local/lib/python3.12/site-packages/sqlalchemy/engine/base.py", line 3374, in _wrap_pool_connect
    Connection._handle_dbapi_exception_noconnection(
  File "/home/airflow/.local/lib/python3.12/site-packages/sqlalchemy/engine/base.py", line 2208, in _handle_dbapi_exception_noconnection
    util.raise_(
  File "/home/airflow/.local/lib/python3.12/site-packages/sqlalchemy/util/compat.py", line 211, in raise_
    raise exception
  File "/home/airflow/.local/lib/python3.12/site-packages/sqlalchemy/engine/base.py", line 3371, in _wrap_pool_connect
    return fn()
           ^^^^
  File "/home/airflow/.local/lib/python3.12/site-packages/sqlalchemy/pool/base.py", line 327, in connect
    return _ConnectionFairy._checkout(self)
           ^^^^^^^^^^^^^^^^^^^^^^^^^^^^^^^^
  File "/home/airflow/.local/lib/python3.12/site-packages/sqlalchemy/pool/base.py", line 894, in _checkout
    fairy = _ConnectionRecord.checkout(pool)
            ^^^^^^^^^^^^^^^^^^^^^^^^^^^^^^^^
  File "/home/airflow/.local/lib/python3.12/site-packages/sqlalchemy/pool/base.py", line 497, in checkout
    with util.safe_reraise():
         ^^^^^^^^^^^^^^^^^^^
  File "/home/airflow/.local/lib/python3.12/site-packages/sqlalchemy/util/langhelpers.py", line 70, in __exit__
    compat.raise_(
  File "/home/airflow/.local/lib/python3.12/site-packages/sqlalchemy/util/compat.py", line 211, in raise_
    raise exception
  File "/home/airflow/.local/lib/python3.12/site-packages/sqlalchemy/pool/base.py", line 495, in checkout
    dbapi_connection = rec.get_connection()
                       ^^^^^^^^^^^^^^^^^^^^
  File "/home/airflow/.local/lib/python3.12/site-packages/sqlalchemy/pool/base.py", line 630, in get_connection
    self.__connect()
  File "/home/airflow/.local/lib/python3.12/site-packages/sqlalchemy/pool/base.py", line 690, in __connect
    with util.safe_reraise():
         ^^^^^^^^^^^^^^^^^^^
  File "/home/airflow/.local/lib/python3.12/site-packages/sqlalchemy/util/langhelpers.py", line 70, in __exit__
    compat.raise_(
  File "/home/airflow/.local/lib/python3.12/site-packages/sqlalchemy/util/compat.py", line 211, in raise_
    raise exception
  File "/home/airflow/.local/lib/python3.12/site-packages/sqlalchemy/pool/base.py", line 686, in __connect
    self.dbapi_connection = connection = pool._invoke_creator(self)
                                         ^^^^^^^^^^^^^^^^^^^^^^^^^^
  File "/home/airflow/.local/lib/python3.12/site-packages/sqlalchemy/engine/create.py", line 574, in connect
    return dialect.connect(*cargs, **cparams)
           ^^^^^^^^^^^^^^^^^^^^^^^^^^^^^^^^^^
  File "/home/airflow/.local/lib/python3.12/site-packages/sqlalchemy/engine/default.py", line 598, in connect
    return self.dbapi.connect(*cargs, **cparams)
           ^^^^^^^^^^^^^^^^^^^^^^^^^^^^^^^^^^^^^
  File "/home/airflow/.local/lib/python3.12/site-packages/psycopg2/__init__.py", line 122, in connect
    conn = _connect(dsn, connection_factory=connection_factory, **kwasync)
           ^^^^^^^^^^^^^^^^^^^^^^^^^^^^^^^^^^^^^^^^^^^^^^^^^^^^^^^^^^^^^^^
sqlalchemy.exc.OperationalError: (psycopg2.OperationalError) connection to server at "postgres" (172.21.0.2), port 5432 failed: FATAL:  the database system is shutting down

(Background on this error at: https://sqlalche.me/e/14/e3q8)
[2024-12-09T01:39:04.697+0000] {processor.py:208} INFO - Processing /home/airflow/.local/lib/python3.12/site-packages/airflow/example_dags/example_trigger_target_dag.py took 0.300 seconds
